# 14.4 exception 소개



```C++

// main.cpp

#include <iostream>
#include <exception>
#include <string>

class CustomException : public std::exception {
public:
    const char *what() const noexcept override {
        return "Custom exception";
    }
};


int main() {


    try {
        std::string s;
        s.resize(-1);   // throw exception
    }
    catch (std::length_error &exception) {
        std::cerr << "Length_Error" << std::endl;
        std::cerr << exception.what() << std::endl;
    }
    catch (std::exception &exception) {

        std::cout << typeid(exception).name() << std::endl;
        std::cerr << exception.what() << std::endl;
    }


    try {
        throw std::runtime_error("Bad thing happened");

    } catch (std::exception &exception) {
        std::cout << typeid(exception).name() << std::endl;
        std::cerr << exception.what() << std::endl;
    }


    try {
        throw CustomException();

    } catch (std::exception &exception) {
        std::cout << typeid(exception).name() << std::endl;
        std::cerr << exception.what() << std::endl;
    }

}

```

